Workbook

Sheet INGRESOS
A1: Servicio de Implementacion MuseIQ - Soporte, IA y Analitica
A3: PROYECCION DE INGRESOS - IMPLEMENTACION MUSEIQ
A4: Concepto | B4: Año 1 | C4: Año 2 | D4: Año 3 | E4: Año 4 | F4: Año 5 | G4: Año 6 | H4: Año 7 | I4: Año 8 | J4: Año 9 | K4: Año 10
A5: Museos nuevos - Basico | B5: 0 | C5: 1 | D5: 0 | E5: 0 | F5: 1 | G5: 0 | H5: 1 | I5: 1 | J5: 1 | K5: 1
A6: Museos nuevos - Estandar | B6: 1 | C6: 0 | D6: 2 | E6: 2 | F6: 2 | G6: 2 | H6: 2 | I6: 3 | J6: 3 | K6: 4
A7: Museos nuevos - Avanzado | B7: 1 | C7: 0 | D7: 0 | E7: 0 | F7: 0 | G7: 1 | H7: 1 | I7: 0 | J7: 1 | K7: 0
A8: Total museos implementados por año | B8: =SUM(B5,B6,B7) -> 2 | C8: =SUM(C5,C6,C7) -> 1 | D8: =SUM(D5,D6,D7) -> 2 | E8: =SUM(E5,E6,E7) -> 2 | F8: =SUM(F5,F6,F7) -> 3 | G8: =SUM(G5,G6,G7) -> 3 | H8: =SUM(H5,H6,H7) -> 4 | I8: =SUM(I5,I6,I7) -> 4 | ... K8: =SUM(K5,K6,K7) -> 5
A9: Ventas implementacion MuseIQ | B9: =(B5*48000+B6*96000+B7*185000)*1.2*B33 -> 337200 | C9: =(C5*48000+C6*96000+C7*185000)*1.2*C33 -> 59328 | D9: =(D5*48000+D6*96000+D7*185000)*1.2*D33 -> 244431.36 | E9: =(E5*48000+E6*96000+E7*185000)*1.2*E33 -> 251764.3 | F9: =(F5*48000+F6*96000+F7*185000)*1.2*F33 -> 324146.54 | G9: =(G5*48000+G6*96000+G7*185000)*1.2*G33 -> 527001.49 | H9: =(H5*48000+H6*96000+H7*185000)*1.2*H33 -> 617863.82 | I9: =(I5*48000+I6*96000+I7*185000)*1.2*I33 -> 508014.9 | ... K9: =(K5*48000+K6*96000+K7*185000)*1.2*K33 -> 706460.04
A10: Servicios adicionales de despliegue | B10: =B9*0.08 -> 26976 | C10: =C9*0.08 -> 4746.24 | D10: =D9*0.08 -> 19554.51 | E10: =E9*0.08 -> 20141.14 | F10: =F9*0.08 -> 25931.72 | G10: =G9*0.08 -> 42160.12 | H10: =H9*0.08 -> 49429.11 | I10: =I9*0.08 -> 40641.19 | ... K10: =K9*0.08 -> 56516.8
A12: INGRESOS - SOPORTE, IA Y ANALITICA
A13: Concepto | B13: Año 1 | C13: Año 2 | D13: Año 3 | E13: Año 4 | F13: Año 5 | G13: Año 6 | H13: Año 7 | I13: Año 8 | J13: Año 9 | K13: Año 10
A14: Museos activos al cierre | B14: =SUM($B$8:B8) -> 2 | C14: =SUM($B$8:C8) -> 3 | D14: =SUM($B$8:D8) -> 5 | E14: =SUM($B$8:E8) -> 7 | F14: =SUM($B$8:F8) -> 10 | G14: =SUM($B$8:G8) -> 13 | H14: =SUM($B$8:H8) -> 17 | I14: =SUM($B$8:I8) -> 21 | ... K14: =SUM($B$8:K8) -> 31
A15: Museos equivalentes recurrentes - Basico | B15: =B5*0.5 -> 0 | C15: =SUM($B$5:B5)+C5*0.5 -> 0.5 | D15: =SUM($B$5:C5)+D5*0.5 -> 1 | E15: =SUM($B$5:D5)+E5*0.5 -> 1 | F15: =SUM($B$5:E5)+F5*0.5 -> 1.5 | G15: =SUM($B$5:F5)+G5*0.5 -> 2 | H15: =SUM($B$5:G5)+H5*0.5 -> 2.5 | I15: =SUM($B$5:H5)+I5*0.5 -> 3.5 | J15: =SUM($B$5:I5)+J5*0.5 -> 4.5 | K15: =SUM($B$5:J5)+K5*0.5 -> 5.5
A16: Museos equivalentes recurrentes - Estandar | B16: =B6*0.5 -> 0.5 | C16: =SUM($B$6:B6)+C6*0.5 -> 1 | D16: =SUM($B$6:C6)+D6*0.5 -> 2 | E16: =SUM($B$6:D6)+E6*0.5 -> 4 | F16: =SUM($B$6:E6)+F6*0.5 -> 6 | G16: =SUM($B$6:F6)+G6*0.5 -> 8 | H16: =SUM($B$6:G6)+H6*0.5 -> 10 | I16: =SUM($B$6:H6)+I6*0.5 -> 12.5 | J16: =SUM($B$6:I6)+J6*0.5 -> 15.5 | K16: =SUM($B$6:J6)+K6*0.5 -> 19
A17: Museos equivalentes recurrentes - Avanzado | B17: =B7*0.5 -> 0.5 | C17: =SUM($B$7:B7)+C7*0.5 -> 1 | D17: =SUM($B$7:C7)+D7*0.5 -> 1 | E17: =SUM($B$7:D7)+E7*0.5 -> 1 | F17: =SUM($B$7:E7)+F7*0.5 -> 1 | G17: =SUM($B$7:F7)+G7*0.5 -> 1.5 | H17: =SUM($B$7:G7)+H7*0.5 -> 2.5 | I17: =SUM($B$7:H7)+I7*0.5 -> 3 | J17: =SUM($B$7:I7)+J7*0.5 -> 3.5 | K17: =SUM($B$7:J7)+K7*0.5 -> 4
A18: Ventas soporte, IA y analitica | B18: =(B15*14000+B16*29000+B17*52000)*1.2*B33 -> 48600 | C18: =(C15*14000+C16*29000+C17*52000)*1.2*C33 -> 108768 | D18: =(D15*14000+D16*29000+D17*52000)*1.2*D33 -> 157861.92 | E18: =(E15*14000+E16*29000+E17*52000)*1.2*E33 -> 238651.58 | F18: =(F15*14000+F16*29000+F17*52000)*1.2*F33 -> 333600.81 | G18: =(G15*14000+G16*29000+G17*52000)*1.2*G33 -> 472484.1 | H18: =(H15*14000+H16*29000+H17*52000)*1.2*H33 -> 661477.73 | I18: =(I15*14000+I16*29000+I17*52000)*1.2*I33 -> 858031.12 | ... K18: =(K15*14000+K16*29000+K17*52000)*1.2*K33 -> 1367131
A19: VENTAS TOTALES | B19: =SUM(B9,B10,B18) -> 412776 | C19: =SUM(C9,C10,C18) -> 172842.24 | D19: =SUM(D9,D10,D18) -> 421847.79 | E19: =SUM(E9,E10,E18) -> 510557.02 | F19: =SUM(F9,F10,F18) -> 683679.07 | G19: =SUM(G9,G10,G18) -> 1041645.7 | H19: =SUM(H9,H10,H18) -> 1328770.7 | I19: =SUM(I9,I10,I18) -> 1406687.2 | ... K19: =SUM(K9,K10,K18) -> 2130107.8
A21: DETERMINACION DE INGRESOS DE EFECTIVO
A22: Concepto | B22: Año 1 | C22: Año 2 | D22: Año 3 | E22: Año 4 | F22: Año 5 | G22: Año 6 | H22: Año 7 | I22: Año 8 | J22: Año 9 | K22: Año 10
A23: Ventas al contado 40% | B23: =B19*0.4 -> 165110.4 | C23: =C19*0.4 -> 69136.9 | D23: =D19*0.4 -> 168739.12 | E23: =E19*0.4 -> 204222.81 | F23: =F19*0.4 -> 273471.63 | G23: =G19*0.4 -> 416658.28 | H23: =H19*0.4 -> 531508.26 | I23: =I19*0.4 -> 562674.88 | ... K23: =K19*0.4 -> 852043.13
A24: Ventas al credito 60% | B24: =B19*0.6 -> 247665.6 | C24: =C19*0.6 -> 103705.34 | D24: =D19*0.6 -> 253108.67 | E24: =E19*0.6 -> 306334.21 | F24: =F19*0.6 -> 410207.44 | G24: =G19*0.6 -> 624987.42 | H24: =H19*0.6 -> 797262.4 | I24: =I19*0.6 -> 844012.33 | ... K24: =K19*0.6 -> 1278064.7
A25: Recuperacion de cuentas por cobrar del año | B25: =B24*0.8*(1-0.0) -> 198132.48 | C25: =C24*0.8*(1-0.0) -> 82964.28 | D25: =D24*0.8*(1-0.0) -> 202486.94 | E25: =E24*0.8*(1-0.0) -> 245067.37 | F25: =F24*0.8*(1-0.0) -> 328165.95 | G25: =G24*0.8*(1-0.0) -> 499989.94 | H25: =H24*0.8*(1-0.0) -> 637809.92 | I25: =I24*0.8*(1-0.0) -> 675209.86 | ... K25: =K24*0.8*(1-0.0) -> 1022451.8
A26: Recuperacion de cuentas por cobrar año anterior | B26: =0 -> 0 | C26: =B28*(1-0.0) -> 49533.12 | D26: =C28*(1-0.0) -> 20741.07 | E26: =D28*(1-0.0) -> 50621.73 | F26: =E28*(1-0.0) -> 61266.84 | G26: =F28*(1-0.0) -> 82041.49 | H26: =G28*(1-0.0) -> 124997.48 | I26: =H28*(1-0.0) -> 159452.48 | J26: =I28*(1-0.0) -> 168802.47 | K26: =J28*(1-0.0) -> 237218.86
A27: TOTAL INGRESOS DE EFECTIVO | B27: =SUM(B23,B25,B26) -> 363242.88 | C27: =SUM(C23,C25,C26) -> 201634.29 | D27: =SUM(D23,D25,D26) -> 391967.12 | E27: =SUM(E23,E25,E26) -> 499911.91 | F27: =SUM(F23,F25,F26) -> 662904.43 | G27: =SUM(G23,G25,G26) -> 998689.71 | H27: =SUM(H23,H25,H26) -> 1294315.7 | I27: =SUM(I23,I25,I26) -> 1397337.2 | ... K27: =SUM(K23,K25,K26) -> 2111713.8
A28: Saldo de cuentas por cobrar al final del año | B28: =B24*(1-0.8) -> 49533.12 | C28: =C24*(1-0.8) -> 20741.07 | D28: =D24*(1-0.8) -> 50621.73 | E28: =E24*(1-0.8) -> 61266.84 | F28: =F24*(1-0.8) -> 82041.49 | G28: =G24*(1-0.8) -> 124997.48 | H28: =H24*(1-0.8) -> 159452.48 | I28: =I24*(1-0.8) -> 168802.47 | ... K28: =K24*(1-0.8) -> 255612.94
A30: INFLACION PROYECTADA Y PRECIOS BASE
A31: Concepto | B31: Año 1 | C31: Año 2 | D31: Año 3 | E31: Año 4 | F31: Año 5 | G31: Año 6 | H31: Año 7 | I31: Año 8 | J31: Año 9 | K31: Año 10
A32: Inflacion anual proyectada | B32: 0.03 | C32: 0.03 | D32: 0.03 | E32: 0.03 | F32: 0.035 | G32: 0.04 | H32: 0.04 | I32: 0.04 | J32: 0.04 | K32: 0.04
A33: Factor acumulado aplicado a precios | B33: =1 -> 1 | C33: =B33*(1+B32) -> 1.03 | D33: =C33*(1+C32) -> 1.0609 | E33: =D33*(1+D32) -> 1.092727 | F33: =E33*(1+E32) -> 1.1255088 | G33: =F33*(1+F32) -> 1.1649016 | H33: =G33*(1+G32) -> 1.2114977 | I33: =H33*(1+H32) -> 1.2599576 | J33: =I33*(1+I32) -> 1.3103559 | K33: =J33*(1+J32) -> 1.3627701
A36: Paquete | B36: Precio base cap. 5 | C36: Precio economico año 1 | D36: Recurrente base cap. 5 | E36: Recurrente economico año 1 | F36: Cobertura | G36: BLE estimados
A37: Basico | B37: 48000 | C37: 57600 | D37: 14000 | E37: 16800 | F37: 3 a 5 salas | G37: 8 a 12
A38: Estandar | B38: 96000 | C38: 115200 | D38: 29000 | E38: 34800 | F38: 6 a 10 salas | G38: 18 a 25
A39: Avanzado | B39: 185000 | C39: 222000 | D39: 52000 | E39: 62400 | F39: 12 a 18 salas | G39: 35 a 45
A41: Nota: el precio economico aplica un factor comercial de 20% sobre los valores del capitulo 5 para cubrir formalizacion, garantia, gestion contractual y contingencia operativa.

Sheet COSTOS
A1: Cuadro de costos de insumos directos anuales
A3: MATERIALES Y SERVICIOS DIRECTOS
A4: Concepto | B4: Año 1 | C4: Año 2 | D4: Año 3 | E4: Año 4 | F4: Año 5 | G4: Año 6 | H4: Año 7 | I4: Año 8 | J4: Año 9 | K4: Año 10
A5: Hardware BLE, señalizacion e instalacion | B5: 77000 | C5: 12360 | D5: 53045 | E5: 54636.35 | F5: 69781.55 | G5: 118819.97 | H5: 138110.74 | I5: 109616.31 | J5: 182139.47 | K5: 152630.25
A6: Nube, voz, IA y soporte variable | B6: 13250 | C6: 29870 | D6: 43496.9 | E6: 65563.62 | F6: 91728.97 | G6: 129886.53 | H6: 181724.65 | I6: 235927.06 | J6: 300399.09 | K6: 376124.56
A7: Curaduria, capacitacion y servicios adicionales | B7: 13488 | C7: 2373.12 | D7: 9777.25 | E7: 10070.57 | F7: 12965.86 | G7: 21080.06 | H7: 24714.55 | I7: 20320.6 | J7: 32769.38 | K7: 28258.4
A8: TOTAL COSTO DIRECTO ANUAL | B8: =SUM(B5,B6,B7) -> 103738 | C8: =SUM(C5,C6,C7) -> 44603.12 | D8: =SUM(D5,D6,D7) -> 106319.15 | E8: =SUM(E5,E6,E7) -> 130270.54 | F8: =SUM(F5,F6,F7) -> 174476.38 | G8: =SUM(G5,G6,G7) -> 269786.56 | H8: =SUM(H5,H6,H7) -> 344549.94 | I8: =SUM(I5,I6,I7) -> 365863.97 | ... K8: =SUM(K5,K6,K7) -> 557013.21
A10: CUADRO DE PRODUCCION - UNIDADES DE SERVICIO
A11: Concepto | B11: Año 1 | C11: Año 2 | D11: Año 3 | E11: Año 4 | F11: Año 5 | G11: Año 6 | H11: Año 7 | I11: Año 8 | J11: Año 9 | K11: Año 10
A12: Museos implementados | B12: 2 | C12: 1 | D12: 2 | E12: 2 | F12: 3 | G12: 3 | H12: 4 | I12: 4 | J12: 5 | K12: 5
A13: Museos activos al cierre | B13: 2 | C13: 3 | D13: 5 | E13: 7 | F13: 10 | G13: 13 | H13: 17 | I13: 21 | J13: 26 | K13: 31
A14: Museos equivalentes recurrentes | B14: 1 | C14: 2.5 | D14: 4 | E14: 6 | F14: 8.5 | G14: 11.5 | H14: 15 | I14: 19 | J14: 23.5 | K14: 28.5
A16: PRESUPUESTO COMPRA DE INSUMOS Y SERVICIOS DIRECTOS
A17: Concepto | B17: Año 1 | C17: Año 2 | D17: Año 3 | E17: Año 4 | F17: Año 5 | G17: Año 6 | H17: Año 7 | I17: Año 8 | J17: Año 9 | K17: Año 10
A18: Compra de contado 30% | B18: =B8*0.3 -> 31121.4 | C18: =C8*0.3 -> 13380.94 | D18: =D8*0.3 -> 31895.75 | E18: =E8*0.3 -> 39081.16 | F18: =F8*0.3 -> 52342.91 | G18: =G8*0.3 -> 80935.97 | H18: =H8*0.3 -> 103364.98 | I18: =I8*0.3 -> 109759.19 | ... K18: =K8*0.3 -> 167103.96
A19: Proveedores credito 70% | B19: =B8*0.7 -> 72616.6 | C19: =C8*0.7 -> 31222.18 | D19: =D8*0.7 -> 74423.41 | E19: =E8*0.7 -> 91189.38 | F19: =F8*0.7 -> 122133.46 | G19: =G8*0.7 -> 188850.59 | H19: =H8*0.7 -> 241184.96 | I19: =I8*0.7 -> 256104.78 | ... K19: =K8*0.7 -> 389909.25
A20: Pago a proveedores en el año | B20: =B19*0.85 -> 61724.11 | C20: =C19*0.85 -> 26538.86 | D20: =D19*0.85 -> 63259.9 | E20: =E19*0.85 -> 77510.97 | F20: =F19*0.85 -> 103813.44 | G20: =G19*0.85 -> 160523 | H20: =H19*0.85 -> 205007.21 | I20: =I19*0.85 -> 217689.06 | ... K20: =K19*0.85 -> 331422.86
A21: Pago a proveedores año anterior | B21: =0 -> 0 | C21: =B23 -> 10892.49 | D21: =C23 -> 4683.33 | E21: =D23 -> 11163.51 | F21: =E23 -> 13678.41 | G21: =F23 -> 18320.02 | H21: =G23 -> 28327.59 | I21: =H23 -> 36177.74 | J21: =I23 -> 38415.72 | K21: =J23 -> 54107.33
A22: TOTAL PAGO A PROVEEDORES | B22: =SUM(B18,B20,B21) -> 92845.51 | C22: =SUM(C18,C20,C21) -> 50812.28 | D22: =SUM(D18,D20,D21) -> 99838.97 | E22: =SUM(E18,E20,E21) -> 127755.65 | F22: =SUM(F18,F20,F21) -> 169834.76 | G22: =SUM(G18,G20,G21) -> 259778.99 | H22: =SUM(H18,H20,H21) -> 336699.79 | I22: =SUM(I18,I20,I21) -> 363625.99 | ... K22: =SUM(K18,K20,K21) -> 552634.16
A23: Saldo cuentas por pagar | B23: =B19*(1-0.85) -> 10892.49 | C23: =C19*(1-0.85) -> 4683.33 | D23: =D19*(1-0.85) -> 11163.51 | E23: =E19*(1-0.85) -> 13678.41 | F23: =F19*(1-0.85) -> 18320.02 | G23: =G19*(1-0.85) -> 28327.59 | H23: =H19*(1-0.85) -> 36177.74 | I23: =I19*(1-0.85) -> 38415.72 | ... K23: =K19*(1-0.85) -> 58486.39
A25: COSTO DE ENERGIA, HERRAMIENTAS Y COSTOS INDIRECTOS
A26: Concepto | B26: Año 1 | C26: Año 2 | D26: Año 3 | E26: Año 4 | F26: Año 5 | G26: Año 6 | H26: Año 7 | I26: Año 8 | J26: Año 9 | K26: Año 10
A27: Energia, internet y comunicaciones | B27: 20000 | C27: 20800 | D27: 21632 | E27: 22497.28 | F27: 23397.17 | G27: 24333.06 | H27: 25306.38 | I27: 26318.64 | J27: 27371.38 | K27: 28466.24
A28: Herramientas cloud, repositorios y monitoreo | B28: 0 | C28: 9000 | D28: 9360 | E28: 9734.4 | F28: 10123.78 | G28: 10528.73 | H28: 10949.88 | I28: 11387.87 | J28: 11843.39 | K28: 12317.12
A29: Papeleria, insumos de oficina y pruebas | B29: 3800 | C29: 3952 | D29: 4110.08 | E29: 4274.48 | F29: 4445.46 | G29: 4623.28 | H29: 4808.21 | I29: 5000.54 | J29: 5200.56 | K29: 5408.58
A30: Mantenimiento menor de equipos | B30: 4500 | C30: 4680 | D30: 4867.2 | E30: 5061.89 | F30: 5264.36 | G30: 5474.94 | H30: 5693.94 | I30: 5921.69 | J30: 6158.56 | K30: 6404.9
A31: Depreciacion asignada a produccion | B31: 14520 | C31: 14520 | D31: 14520 | E31: 14520 | F31: 7320 | G31: 1080 | H31: 1080 | I31: 1080 | J31: 1080 | K31: 1080
A32: TOTAL COSTO INDIRECTO DE PRODUCCION | B32: =SUM(B27,B28,B29,B30,B31) -> 42820 | C32: =SUM(C27,C28,C29,C30,C31) -> 52952 | D32: =SUM(D27,D28,D29,D30,D31) -> 54489.28 | E32: =SUM(E27,E28,E29,E30,E31) -> 56088.05 | F32: =SUM(F27,F28,F29,F30,F31) -> 50550.77 | G32: =SUM(G27,G28,G29,G30,G31) -> 46040 | H32: =SUM(H27,H28,H29,H30,H31) -> 47838.4 | I32: =SUM(I27,I28,I29,I30,I31) -> 49708.74 | ... K32: =SUM(K27,K28,K29,K30,K31) -> 53676.85
A35: Descripcion de equipos de operacion anual | B35: Potencia/uso | C35: % produccion | D35: % ventas | E35: % adm.
A36: Laptops de desarrollo y pruebas | B36: 8 h/dia | C36: 0.65 | D36: 0.1 | E36: 0.25
A37: Servidor local/NAS para RAG y datos | B37: 24 h/dia | C37: 0.8 | D37: 0 | E37: 0.2
A38: Smartphones/tablets de prueba | B38: 4 h/dia | C38: 0.7 | D38: 0.1 | E38: 0.2
A39: Red WiFi, router y UPS | B39: 24 h/dia | C39: 0.6 | D39: 0.2 | E39: 0.2

Sheet COSTO DE PRODUCCION UNITARIO
A1: Costo Total de Operacion - MuseIQ
A4: Concepto | B4: Año 1 | C4: Año 2 | D4: Año 3 | E4: Año 4 | F4: Año 5 | G4: Año 6 | H4: Año 7 | I4: Año 8 | J4: Año 9 | K4: Año 10
A5: Insumos y servicios directos | B5: 103738 | C5: 44603.12 | D5: 106319.15 | E5: 130270.54 | F5: 174476.38 | G5: 269786.56 | H5: 344549.94 | I5: 365863.97 | J5: 515307.94 | K5: 557013.21
A6: Mano de obra directa | B6: 68068.89 | C6: 103034.81 | D6: 128651.64 | E6: 133797.71 | F6: 139149.62 | G6: 168002.33 | H6: 174722.42 | I6: 208580.62 | J6: 216923.84 | K6: 225600.79
A7: Costos indirectos de servicio | B7: 42820 | C7: 52952 | D7: 54489.28 | E7: 56088.05 | F7: 50550.77 | G7: 46040 | H7: 47838.4 | I7: 49708.74 | J7: 51653.89 | K7: 53676.85
A8: TOTAL COSTO DE PRODUCCION | B8: =SUM(B5,B6,B7) -> 214626.89 | C8: =SUM(C5,C6,C7) -> 200589.93 | D8: =SUM(D5,D6,D7) -> 289460.08 | E8: =SUM(E5,E6,E7) -> 320156.3 | F8: =SUM(F5,F6,F7) -> 364176.76 | G8: =SUM(G5,G6,G7) -> 483828.89 | H8: =SUM(H5,H6,H7) -> 567110.77 | I8: =SUM(I5,I6,I7) -> 624153.32 | ... K8: =SUM(K5,K6,K7) -> 836290.85
A9: Costo unitario por museo equivalente | B9: =B8/MAX(1,'COSTOS'!B12+'COSTOS'!B14) -> 71542.3 | C9: =C8/MAX(1,'COSTOS'!C12+'COSTOS'!C14) -> 57311.41 | D9: =D8/MAX(1,'COSTOS'!D12+'COSTOS'!D14) -> 48243.35 | E9: =E8/MAX(1,'COSTOS'!E12+'COSTOS'!E14) -> 40019.54 | F9: =F8/MAX(1,'COSTOS'!F12+'COSTOS'!F14) -> 31667.54 | G9: =G8/MAX(1,'COSTOS'!G12+'COSTOS'!G14) -> 33367.51 | H9: =H8/MAX(1,'COSTOS'!H12+'COSTOS'!H14) -> 29847.94 | I9: =I8/MAX(1,'COSTOS'!I12+'COSTOS'!I14) -> 27137.1 | ... K9: =K8/MAX(1,'COSTOS'!K12+'COSTOS'!K14) -> 24963.91
A11: El costo unitario se expresa por museo equivalente: museos implementados en el año mas museos recurrentes ponderados.

Sheet PLANILLA
A1: Prestacion de servicios por año - Planilla MuseIQ
A3: PRESTACION DE SERVICIOS POR AÑO 1
A4: CARGO | B4: SUELDO MENSUAL | C4: SUELDO ANUAL | D4: GRATIFICACION JULIO DICIEMBRE | E4: ESSALUD (9%) | F4: CTS (8.33%) | G4: VACACIONES | H4: PREAVISO | I4: CESANTIA | J4: TOTAL C. SOCIAL | K4: TOTAL
A5: Administracion
A6: Gerente general - financiero | B6: 1800 | C6: =B6*12 -> 21600 | D6: =B6*2 -> 3600 | E6: =C6*9% -> 1944 | F6: =(C6+D6)*8.33% -> 2099.16 | G6: =B6*0.5 -> 900 | H6: =0 -> 0 | I6: =B6*14/12 -> 2100 | J6: =SUM(D6:I6) -> 10643.16 | K6: =C6+J6 -> 32243.16
A7: Asistente contable administrativo | B7: 900 | C7: =B7*12 -> 10800 | D7: =B7*2 -> 1800 | E7: =C7*9% -> 972 | F7: =(C7+D7)*8.33% -> 1049.58 | G7: =B7*0.5 -> 450 | H7: =0 -> 0 | I7: =B7*14/12 -> 1050 | J7: =SUM(D7:I7) -> 5321.58 | K7: =C7+J7 -> 16121.58
A8: TOTAL PLANILLA ADMINISTRACION | K8: =SUM(K6:K7) -> 48364.74
A9: Produccion MuseIQ
A10: Lider backend, RAG y plataforma | B10: 2500 | C10: =B10*12 -> 30000 | D10: =B10*2 -> 5000 | E10: =C10*9% -> 2700 | F10: =(C10+D10)*8.33% -> 2915.5 | G10: =B10*0.5 -> 1250 | H10: =0 -> 0 | I10: =B10*14/12 -> 2916.67 | J10: =SUM(D10:I10) -> 14782.17 | K10: =C10+J10 -> 44782.17
A11: Especialista curatorial y datos | B11: 1300 | C11: =B11*12 -> 15600 | D11: =B11*2 -> 2600 | E11: =C11*9% -> 1404 | F11: =(C11+D11)*8.33% -> 1516.06 | G11: =B11*0.5 -> 650 | H11: =0 -> 0 | I11: =B11*14/12 -> 1516.67 | J11: =SUM(D11:I11) -> 7686.73 | K11: =C11+J11 -> 23286.73
A12: TOTAL PLANILLA PRODUCCION MUSEIQ | K12: =SUM(K10:K11) -> 68068.89
A13: Ventas
A14: Ejecutivo comercial institucional | B14: 1700 | C14: =B14*12 -> 20400 | D14: =B14*2 -> 3400 | E14: =C14*9% -> 1836 | F14: =(C14+D14)*8.33% -> 1982.54 | G14: =B14*0.5 -> 850 | H14: =0 -> 0 | I14: =B14*14/12 -> 1983.33 | J14: =SUM(D14:I14) -> 10051.87 | K14: =C14+J14 -> 30451.87
A15: TOTAL PLANILLA VENTAS | K15: =SUM(K14:K14) -> 30451.87
A18: PRESTACION DE SERVICIOS POR AÑO 2
A19: CARGO | B19: SUELDO MENSUAL | C19: SUELDO ANUAL | D19: GRATIFICACION JULIO DICIEMBRE | E19: ESSALUD (9%) | F19: CTS (8.33%) | G19: VACACIONES | H19: PREAVISO | I19: CESANTIA | J19: TOTAL C. SOCIAL | K19: TOTAL
A20: Administracion
A21: Gerente general - financiero | B21: 1872 | C21: =B21*12 -> 22464 | D21: =B21*2 -> 3744 | E21: =C21*9% -> 2021.76 | F21: =(C21+D21)*8.33% -> 2183.13 | G21: =B21*0.5 -> 936 | H21: =0 -> 0 | I21: =B21*14/12 -> 2184 | J21: =SUM(D21:I21) -> 11068.89 | K21: =C21+J21 -> 33532.89
A22: Asistente contable administrativo | B22: 936 | C22: =B22*12 -> 11232 | D22: =B22*2 -> 1872 | E22: =C22*9% -> 1010.88 | F22: =(C22+D22)*8.33% -> 1091.56 | G22: =B22*0.5 -> 468 | H22: =0 -> 0 | I22: =B22*14/12 -> 1092 | J22: =SUM(D22:I22) -> 5534.44 | K22: =C22+J22 -> 16766.44
A23: TOTAL PLANILLA ADMINISTRACION | K23: =SUM(K21:K22) -> 50299.33
A24: Produccion MuseIQ
A25: Lider backend, RAG y plataforma | B25: 2600 | C25: =B25*12 -> 31200 | D25: =B25*2 -> 5200 | E25: =C25*9% -> 2808 | F25: =(C25+D25)*8.33% -> 3032.12 | G25: =B25*0.5 -> 1300 | H25: =0 -> 0 | I25: =B25*14/12 -> 3033.33 | J25: =SUM(D25:I25) -> 15373.45 | K25: =C25+J25 -> 46573.45
A26: Especialista curatorial y datos | B26: 1352 | C26: =B26*12 -> 16224 | D26: =B26*2 -> 2704 | E26: =C26*9% -> 1460.16 | F26: =(C26+D26)*8.33% -> 1576.7 | G26: =B26*0.5 -> 676 | H26: =0 -> 0 | I26: =B26*14/12 -> 1577.33 | J26: =SUM(D26:I26) -> 7994.2 | K26: =C26+J26 -> 24218.2
A27: Ingeniero mobile e IoT BLE | B27: 1800 | C27: =B27*12 -> 21600 | D27: =B27*2 -> 3600 | E27: =C27*9% -> 1944 | F27: =(C27+D27)*8.33% -> 2099.16 | G27: =B27*0.5 -> 900 | H27: =0 -> 0 | I27: =B27*14/12 -> 2100 | J27: =SUM(D27:I27) -> 10643.16 | K27: =C27+J27 -> 32243.16
A28: TOTAL PLANILLA PRODUCCION MUSEIQ | K28: =SUM(K25:K27) -> 103034.81
A29: Ventas
A30: Ejecutivo comercial institucional | B30: 1768 | C30: =B30*12 -> 21216 | D30: =B30*2 -> 3536 | E30: =C30*9% -> 1909.44 | F30: =(C30+D30)*8.33% -> 2061.84 | G30: =B30*0.5 -> 884 | H30: =0 -> 0 | I30: =B30*14/12 -> 2062.67 | J30: =SUM(D30:I30) -> 10453.95 | K30: =C30+J30 -> 31669.95
A31: TOTAL PLANILLA VENTAS | K31: =SUM(K30:K30) -> 31669.95
A34: PRESTACION DE SERVICIOS POR AÑO 3
A35: CARGO | B35: SUELDO MENSUAL | C35: SUELDO ANUAL | D35: GRATIFICACION JULIO DICIEMBRE | E35: ESSALUD (9%) | F35: CTS (8.33%) | G35: VACACIONES | H35: PREAVISO | I35: CESANTIA | J35: TOTAL C. SOCIAL | K35: TOTAL
A36: Administracion
A37: Gerente general - financiero | B37: 1946.88 | C37: =B37*12 -> 23362.56 | D37: =B37*2 -> 3893.76 | E37: =C37*9% -> 2102.63 | F37: =(C37+D37)*8.33% -> 2270.45 | G37: =B37*0.5 -> 973.44 | H37: =0 -> 0 | I37: =B37*14/12 -> 2271.36 | J37: =SUM(D37:I37) -> 11511.64 | K37: =C37+J37 -> 34874.2
A38: Asistente contable administrativo | B38: 973.44 | C38: =B38*12 -> 11681.28 | D38: =B38*2 -> 1946.88 | E38: =C38*9% -> 1051.32 | F38: =(C38+D38)*8.33% -> 1135.23 | G38: =B38*0.5 -> 486.72 | H38: =0 -> 0 | I38: =B38*14/12 -> 1135.68 | J38: =SUM(D38:I38) -> 5755.82 | K38: =C38+J38 -> 17437.1
A39: TOTAL PLANILLA ADMINISTRACION | K39: =SUM(K37:K38) -> 52311.3
A40: Produccion MuseIQ
A41: Lider backend, RAG y plataforma | B41: 2704 | C41: =B41*12 -> 32448 | D41: =B41*2 -> 5408 | E41: =C41*9% -> 2920.32 | F41: =(C41+D41)*8.33% -> 3153.4 | G41: =B41*0.5 -> 1352 | H41: =0 -> 0 | I41: =B41*14/12 -> 3154.67 | J41: =SUM(D41:I41) -> 15988.39 | K41: =C41+J41 -> 48436.39
A42: Especialista curatorial y datos | B42: 1406.08 | C42: =B42*12 -> 16872.96 | D42: =B42*2 -> 2812.16 | E42: =C42*9% -> 1518.57 | F42: =(C42+D42)*8.33% -> 1639.77 | G42: =B42*0.5 -> 703.04 | H42: =0 -> 0 | I42: =B42*14/12 -> 1640.43 | J42: =SUM(D42:I42) -> 8313.96 | K42: =C42+J42 -> 25186.92
A43: Ingeniero mobile e IoT BLE | B43: 1872 | C43: =B43*12 -> 22464 | D43: =B43*2 -> 3744 | E43: =C43*9% -> 2021.76 | F43: =(C43+D43)*8.33% -> 2183.13 | G43: =B43*0.5 -> 936 | H43: =0 -> 0 | I43: =B43*14/12 -> 2184 | J43: =SUM(D43:I43) -> 11068.89 | K43: =C43+J43 -> 33532.89
A44: Soporte tecnico y QA | B44: 1200 | C44: =B44*12 -> 14400 | D44: =B44*2 -> 2400 | E44: =C44*9% -> 1296 | F44: =(C44+D44)*8.33% -> 1399.44 | G44: =B44*0.5 -> 600 | H44: =0 -> 0 | I44: =B44*14/12 -> 1400 | J44: =SUM(D44:I44) -> 7095.44 | K44: =C44+J44 -> 21495.44
A45: TOTAL PLANILLA PRODUCCION MUSEIQ | K45: =SUM(K41:K44) -> 128651.64
...

Sheet GASTOS_ADM_VTAS_FINANZAS
A1: Gastos de Venta, Administracion y Finanzas
A3: GASTOS DE VENTA
A4: Concepto | B4: Año 1 | C4: Año 2 | D4: Año 3 | E4: Año 4 | F4: Año 5 | G4: Año 6 | H4: Año 7 | I4: Año 8 | J4: Año 9 | K4: Año 10
A5: Sueldo y carga social depto. venta | B5: 30451.87 | C5: 31669.95 | D5: 32936.75 | E5: 61123.52 | F5: 63568.46 | G5: 66111.19 | H5: 68755.64 | I5: 94792.6 | J5: 98584.3 | K5: 102527.67
A6: Comisiones a vendedores 2.5% ventas | B6: ='INGRESOS'!B19*2.5% -> 10319.4 | C6: ='INGRESOS'!C19*2.5% -> 4321.06 | D6: ='INGRESOS'!D19*2.5% -> 10546.19 | E6: ='INGRESOS'!E19*2.5% -> 12763.93 | F6: ='INGRESOS'!F19*2.5% -> 17091.98 | G6: ='INGRESOS'!G19*2.5% -> 26041.14 | H6: ='INGRESOS'!H19*2.5% -> 33219.27 | I6: ='INGRESOS'!I19*2.5% -> 35167.18 | ... K6: ='INGRESOS'!K19*2.5% -> 53252.7
A7: Prospeccion, viajes y representacion | B7: =16000*(1.04^0) -> 16000 | C7: =16000*(1.04^1) -> 16640 | D7: =16000*(1.04^2) -> 17305.6 | E7: =16000*(1.04^3) -> 17997.82 | F7: =16000*(1.04^4) -> 18717.74 | G7: =16000*(1.04^5) -> 19466.45 | H7: =16000*(1.04^6) -> 20245.1 | I7: =16000*(1.04^7) -> 21054.91 | J7: =16000*(1.04^8) -> 21897.1 | K7: =16000*(1.04^9) -> 22772.99
A8: TOTAL GASTOS DE VENTA | B8: =SUM(B5,B6,B7) -> 56771.27 | C8: =SUM(C5,C6,C7) -> 52631 | D8: =SUM(D5,D6,D7) -> 60788.54 | E8: =SUM(E5,E6,E7) -> 91885.27 | F8: =SUM(F5,F6,F7) -> 99378.17 | G8: =SUM(G5,G6,G7) -> 111618.78 | H8: =SUM(H5,H6,H7) -> 122220.01 | I8: =SUM(I5,I6,I7) -> 151014.68 | ... K8: =SUM(K5,K6,K7) -> 178553.36
A10: GASTOS DE ADMINISTRACION
A11: Concepto | B11: Año 1 | C11: Año 2 | D11: Año 3 | E11: Año 4 | F11: Año 5 | G11: Año 6 | H11: Año 7 | I11: Año 8 | J11: Año 9 | K11: Año 10
A12: Sueldo y carga social administracion | B12: 48364.74 | C12: 50299.33 | D12: 52311.3 | E12: 54403.75 | F12: 78075.35 | G12: 81198.36 | H12: 84446.29 | I12: 87824.14 | J12: 91337.11 | K12: 94990.6
A13: Servicios contables, legales, oficina y comunicaciones | B13: 16000 | C13: 16640 | D13: 17305.6 | E13: 17997.82 | F13: 18717.74 | G13: 19466.45 | H13: 20245.1 | I13: 21054.91 | J13: 21897.1 | K13: 22772.99
A14: Depreciacion y amortizacion asignada | B14: ='DEPRECIACIONES AMORTIZACION'!B11*40%+'DEPRECIACIONES AMORTIZACION'!B23 -> 36080 | C14: ='DEPRECIACIONES AMORTIZACION'!C11*40%+'DEPRECIACIONES AMORTIZACION'!C23 -> 36080 | D14: ='DEPRECIACIONES AMORTIZACION'!D11*40%+'DEPRECIACIONES AMORTIZACION'!D23 -> 36080 | E14: ='DEPRECIACIONES AMORTIZACION'!E11*40%+'DEPRECIACIONES AMORTIZACION'!E23 -> 36080 | F14: ='DEPRECIACIONES AMORTIZACION'!F11*40%+'DEPRECIACIONES AMORTIZACION'!F23 -> 31280 | G14: ='DEPRECIACIONES AMORTIZACION'!G11*40%+'DEPRECIACIONES AMORTIZACION'!G23 -> 720 | H14: ='DEPRECIACIONES AMORTIZACION'!H11*40%+'DEPRECIACIONES AMORTIZACION'!H23 -> 720 | I14: ='DEPRECIACIONES AMORTIZACION'!I11*40%+'DEPRECIACIONES AMORTIZACION'!I23 -> 720 | ... K14: ='DEPRECIACIONES AMORTIZACION'!K11*40%+'DEPRECIACIONES AMORTIZACION'!K23 -> 720
A15: TOTAL GASTOS ADMINISTRATIVOS | B15: =SUM(B12,B13,B14) -> 100444.74 | C15: =SUM(C12,C13,C14) -> 103019.33 | D15: =SUM(D12,D13,D14) -> 105696.9 | E15: =SUM(E12,E13,E14) -> 108481.58 | F15: =SUM(F12,F13,F14) -> 128073.08 | G15: =SUM(G12,G13,G14) -> 101384.81 | H15: =SUM(H12,H13,H14) -> 105411.4 | I15: =SUM(I12,I13,I14) -> 109599.05 | ... K15: =SUM(K12,K13,K14) -> 118483.58
A17: GASTOS FINANCIEROS - AMORTIZACION DEL PRESTAMO
A18: Concepto | B18: Año 1 | C18: Año 2 | D18: Año 3 | E18: Año 4 | F18: Año 5 | G18: Año 6 | H18: Año 7 | I18: Año 8 | J18: Año 9 | K18: Año 10
A19: Saldo inicial de deuda | B19: =180000.0 -> 180000 | C19: =B23 -> 180000 | D19: =C23 -> 180000 | E19: =D23 -> 160936.18 | F19: =E23 -> 138440.87 | G19: =F23 -> 111896.4 | H19: =G23 -> 80573.93 | I19: =H23 -> 43613.41 | J19: =I23 -> 0 | K19: =J23 -> 0
A20: Intereses | B20: =B19*0.18 -> 32400 | C20: =C19*0.18 -> 32400 | D20: =D19*0.18 -> 32400 | E20: =E19*0.18 -> 28968.51 | F20: =F19*0.18 -> 24919.36 | G20: =G19*0.18 -> 20141.35 | H20: =H19*0.18 -> 14503.31 | I20: =I19*0.18 -> 7850.41 | ... K20: =K19*0.18 -> 0
A21: Abono a capital | B21: =IF(COLUMN(B1)-COLUMN($B$1)+1<=2,0,IF(COLUMN(B1)-COLUMN($B$1)+1<=8,MIN(PMT(0.18,6,-180000.0)-B20,B19),0)) -> 0 | C21: =IF(COLUMN(C1)-COLUMN($B$1)+1<=2,0,IF(COLUMN(C1)-COLUMN($B$1)+1<=8,MIN(PMT(0.18,6,-180000.0)-C20,C19),0)) -> 0 | D21: =IF(COLUMN(D1)-COLUMN($B$1)+1<=2,0,IF(COLUMN(D1)-COLUMN($B$1)+1<=8,MIN(PMT(0.18,6,-180000.0)-D20,D19),0)) -> 19063.82 | E21: =IF(COLUMN(E1)-COLUMN($B$1)+1<=2,0,IF(COLUMN(E1)-COLUMN($B$1)+1<=8,MIN(PMT(0.18,6,-180000.0)-E20,E19),0)) -> 22495.31 | F21: =IF(COLUMN(F1)-COLUMN($B$1)+1<=2,0,IF(COLUMN(F1)-COLUMN($B$1)+1<=8,MIN(PMT(0.18,6,-180000.0)-F20,F19),0)) -> 26544.47 | G21: =IF(COLUMN(G1)-COLUMN($B$1)+1<=2,0,IF(COLUMN(G1)-COLUMN($B$1)+1<=8,MIN(PMT(0.18,6,-180000.0)-G20,G19),0)) -> 31322.47 | H21: =IF(COLUMN(H1)-COLUMN($B$1)+1<=2,0,IF(COLUMN(H1)-COLUMN($B$1)+1<=8,MIN(PMT(0.18,6,-180000.0)-H20,H19),0)) -> 36960.52 | I21: =IF(COLUMN(I1)-COLUMN($B$1)+1<=2,0,IF(COLUMN(I1)-COLUMN($B$1)+1<=8,MIN(PMT(0.18,6,-180000.0)-I20,I19),0)) -> 43613.41 | ... K21: =IF(COLUMN(K1)-COLUMN($B$1)+1<=2,0,IF(COLUMN(K1)-COLUMN($B$1)+1<=8,MIN(PMT(0.18,6,-180000.0)-K20,K19),0)) -> 0
A22: Cuota anual | B22: =SUM(B20,B21) -> 32400 | C22: =SUM(C20,C21) -> 32400 | D22: =SUM(D20,D21) -> 51463.82 | E22: =SUM(E20,E21) -> 51463.82 | F22: =SUM(F20,F21) -> 51463.82 | G22: =SUM(G20,G21) -> 51463.82 | H22: =SUM(H20,H21) -> 51463.82 | I22: =SUM(I20,I21) -> 51463.82 | ... K22: =SUM(K20,K21) -> 0
A23: Saldo final de deuda | B23: =MAX(0,B19-B21) -> 180000 | C23: =MAX(0,C19-C21) -> 180000 | D23: =MAX(0,D19-D21) -> 160936.18 | E23: =MAX(0,E19-E21) -> 138440.87 | F23: =MAX(0,F19-F21) -> 111896.4 | G23: =MAX(0,G19-G21) -> 80573.93 | H23: =MAX(0,H19-H21) -> 43613.41 | I23: =MAX(0,I19-I21) -> 0 | ... K23: =MAX(0,K19-K21) -> 0
A25: Condicion adoptada: 2 años de gracia de capital y amortizacion en 6 cuotas anuales; tasa base 18% anual.

Sheet DEPRECIACIONES AMORTIZACION
A1: Depreciaciones y Amortizacion
A3: ACTIVOS TANGIBLES
A4: Activo | B4: Valor | C4: Vida util
A5: Laptops y equipos de prueba | B5: 48000 | C5: 4
A6: Servidor/NAS y red local | B6: 32000 | C6: 5
A7: Herramientas de instalacion y medicion | B7: 20000 | C7: 5
A8: Mobiliario y oficina | B8: 18000 | C8: 10
A10: Concepto | B10: Año 1 | C10: Año 2 | D10: Año 3 | E10: Año 4 | F10: Año 5 | G10: Año 6 | H10: Año 7 | I10: Año 8 | J10: Año 9 | K10: Año 10
A11: Depreciacion anual | B11: =IF(1<=$C$5,$B$5/$C$5,0)+IF(1<=$C$6,$B$6/$C$6,0)+IF(1<=$C$7,$B$7/$C$7,0)+IF(1<=$C$8,$B$8/$C$8,0) -> 24200 | C11: =IF(2<=$C$5,$B$5/$C$5,0)+IF(2<=$C$6,$B$6/$C$6,0)+IF(2<=$C$7,$B$7/$C$7,0)+IF(2<=$C$8,$B$8/$C$8,0) -> 24200 | D11: =IF(3<=$C$5,$B$5/$C$5,0)+IF(3<=$C$6,$B$6/$C$6,0)+IF(3<=$C$7,$B$7/$C$7,0)+IF(3<=$C$8,$B$8/$C$8,0) -> 24200 | E11: =IF(4<=$C$5,$B$5/$C$5,0)+IF(4<=$C$6,$B$6/$C$6,0)+IF(4<=$C$7,$B$7/$C$7,0)+IF(4<=$C$8,$B$8/$C$8,0) -> 24200 | F11: =IF(5<=$C$5,$B$5/$C$5,0)+IF(5<=$C$6,$B$6/$C$6,0)+IF(5<=$C$7,$B$7/$C$7,0)+IF(5<=$C$8,$B$8/$C$8,0) -> 12200 | G11: =IF(6<=$C$5,$B$5/$C$5,0)+IF(6<=$C$6,$B$6/$C$6,0)+IF(6<=$C$7,$B$7/$C$7,0)+IF(6<=$C$8,$B$8/$C$8,0) -> 1800 | H11: =IF(7<=$C$5,$B$5/$C$5,0)+IF(7<=$C$6,$B$6/$C$6,0)+IF(7<=$C$7,$B$7/$C$7,0)+IF(7<=$C$8,$B$8/$C$8,0) -> 1800 | I11: =IF(8<=$C$5,$B$5/$C$5,0)+IF(8<=$C$6,$B$6/$C$6,0)+IF(8<=$C$7,$B$7/$C$7,0)+IF(8<=$C$8,$B$8/$C$8,0) -> 1800 | J11: =IF(9<=$C$5,$B$5/$C$5,0)+IF(9<=$C$6,$B$6/$C$6,0)+IF(9<=$C$7,$B$7/$C$7,0)+IF(9<=$C$8,$B$8/$C$8,0) -> 1800 | K11: =IF(10<=$C$5,$B$5/$C$5,0)+IF(10<=$C$6,$B$6/$C$6,0)+IF(10<=$C$7,$B$7/$C$7,0)+IF(10<=$C$8,$B$8/$C$8,0) -> 1800
A12: Activo fijo neto | B12: =MAX(0,SUM($B$5:$B$8)-SUM($B$11:B11)) -> 93800 | C12: =MAX(0,SUM($B$5:$B$8)-SUM($B$11:C11)) -> 69600 | D12: =MAX(0,SUM($B$5:$B$8)-SUM($B$11:D11)) -> 45400 | E12: =MAX(0,SUM($B$5:$B$8)-SUM($B$11:E11)) -> 21200 | F12: =MAX(0,SUM($B$5:$B$8)-SUM($B$11:F11)) -> 9000 | G12: =MAX(0,SUM($B$5:$B$8)-SUM($B$11:G11)) -> 7200 | H12: =MAX(0,SUM($B$5:$B$8)-SUM($B$11:H11)) -> 5400 | I12: =MAX(0,SUM($B$5:$B$8)-SUM($B$11:I11)) -> 3600 | ... K12: =MAX(0,SUM($B$5:$B$8)-SUM($B$11:K11)) -> 0
A15: ACTIVOS INTANGIBLES Y DIFERIDOS
A16: Activo | B16: Valor | C16: Vida util
A17: Constitucion y formalizacion | B17: 8000 | C17: 5
A18: Desarrollo base app/API/RAG | B18: 90000 | C18: 5
A19: Documentacion y manuales | B19: 22000 | C19: 5
A20: Marca, preventa y dossier comercial | B20: 12000 | C20: 5
A22: Concepto | B22: Año 1 | C22: Año 2 | D22: Año 3 | E22: Año 4 | F22: Año 5 | G22: Año 6 | H22: Año 7 | I22: Año 8 | J22: Año 9 | K22: Año 10
A23: Amortizacion anual | B23: =IF(1<=$C$17,$B$17/$C$17,0)+IF(1<=$C$18,$B$18/$C$18,0)+IF(1<=$C$19,$B$19/$C$19,0)+IF(1<=$C$20,$B$20/$C$20,0) -> 26400 | C23: =IF(2<=$C$17,$B$17/$C$17,0)+IF(2<=$C$18,$B$18/$C$18,0)+IF(2<=$C$19,$B$19/$C$19,0)+IF(2<=$C$20,$B$20/$C$20,0) -> 26400 | D23: =IF(3<=$C$17,$B$17/$C$17,0)+IF(3<=$C$18,$B$18/$C$18,0)+IF(3<=$C$19,$B$19/$C$19,0)+IF(3<=$C$20,$B$20/$C$20,0) -> 26400 | E23: =IF(4<=$C$17,$B$17/$C$17,0)+IF(4<=$C$18,$B$18/$C$18,0)+IF(4<=$C$19,$B$19/$C$19,0)+IF(4<=$C$20,$B$20/$C$20,0) -> 26400 | F23: =IF(5<=$C$17,$B$17/$C$17,0)+IF(5<=$C$18,$B$18/$C$18,0)+IF(5<=$C$19,$B$19/$C$19,0)+IF(5<=$C$20,$B$20/$C$20,0) -> 26400 | G23: =IF(6<=$C$17,$B$17/$C$17,0)+IF(6<=$C$18,$B$18/$C$18,0)+IF(6<=$C$19,$B$19/$C$19,0)+IF(6<=$C$20,$B$20/$C$20,0) -> 0 | H23: =IF(7<=$C$17,$B$17/$C$17,0)+IF(7<=$C$18,$B$18/$C$18,0)+IF(7<=$C$19,$B$19/$C$19,0)+IF(7<=$C$20,$B$20/$C$20,0) -> 0 | I23: =IF(8<=$C$17,$B$17/$C$17,0)+IF(8<=$C$18,$B$18/$C$18,0)+IF(8<=$C$19,$B$19/$C$19,0)+IF(8<=$C$20,$B$20/$C$20,0) -> 0 | J23: =IF(9<=$C$17,$B$17/$C$17,0)+IF(9<=$C$18,$B$18/$C$18,0)+IF(9<=$C$19,$B$19/$C$19,0)+IF(9<=$C$20,$B$20/$C$20,0) -> 0 | K23: =IF(10<=$C$17,$B$17/$C$17,0)+IF(10<=$C$18,$B$18/$C$18,0)+IF(10<=$C$19,$B$19/$C$19,0)+IF(10<=$C$20,$B$20/$C$20,0) -> 0
A24: Activo intangible neto | B24: =MAX(0,SUM($B$17:$B$20)-SUM($B$23:B23)) -> 105600 | C24: =MAX(0,SUM($B$17:$B$20)-SUM($B$23:C23)) -> 79200 | D24: =MAX(0,SUM($B$17:$B$20)-SUM($B$23:D23)) -> 52800 | E24: =MAX(0,SUM($B$17:$B$20)-SUM($B$23:E23)) -> 26400 | F24: =MAX(0,SUM($B$17:$B$20)-SUM($B$23:F23)) -> 0 | G24: =MAX(0,SUM($B$17:$B$20)-SUM($B$23:G23)) -> 0 | H24: =MAX(0,SUM($B$17:$B$20)-SUM($B$23:H23)) -> 0 | I24: =MAX(0,SUM($B$17:$B$20)-SUM($B$23:I23)) -> 0 | ... K24: =MAX(0,SUM($B$17:$B$20)-SUM($B$23:K23)) -> 0

Sheet PLAN DE INVERSION
A1: Plan de Inversion - MuseIQ
A4: Concepto | B4: Monto | C4: Criterio
A5: Activos tangibles | B5: 118000 | C5: Equipos de prueba, servidor, herramientas y mobiliario
A6: Activos intangibles y diferidos | B6: 132000 | C6: Desarrollo base, formalizacion, documentacion y preventa
A7: Capital de trabajo inicial | B7: 50000 | C7: Caja de arranque para cubrir descalce de cobros y pagos
A8: TOTAL INVERSION | B8: =SUM(B5:B7) -> 300000 | C8: Base del flujo de efectivo
A9: Fondos propios | B9: =B8*0.4 -> 120000 | C9: 40% de la inversion
A10: Financiamiento | B10: =B8*0.6 -> 180000 | C10: 60% de la inversion

Sheet BALANCE DE APERTURA
A1: Balance de Apertura
A4: Activos
A5: Caja y bancos | B5: 50000 | C5: Activo circulante
A6: Mobiliario, equipos y herramientas | B6: 118000 | C6: Activo fijo
A7: Activos intangibles y diferidos | B7: 132000 | C7: Nominales
A8: TOTAL ACTIVOS | B8: =SUM(B5:B7) -> 300000
A9: Pasivos
A10: Prestamo bancario | B10: 180000 | C10: Pasivo largo plazo
A11: Patrimonio
A12: Capital social | B12: 120000 | C12: Fondos propios
A13: TOTAL PASIVO Y PATRIMONIO | B13: =B10+B12 -> 300000

Sheet COSTO DE VENTA
A1: Costo de lo Vendido
A4: Concepto | B4: Año 1 | C4: Año 2 | D4: Año 3 | E4: Año 4 | F4: Año 5 | G4: Año 6 | H4: Año 7 | I4: Año 8 | J4: Año 9 | K4: Año 10
A5: Inventario inicial | B5: 0 | C5: 0 | D5: 0 | E5: 0 | F5: 0 | G5: 0 | H5: 0 | I5: 0 | J5: 0 | K5: 0
A6: + Costo de produccion | B6: ='COSTO DE PRODUCCION UNITARIO'!B8 -> 214626.89 | C6: ='COSTO DE PRODUCCION UNITARIO'!C8 -> 200589.93 | D6: ='COSTO DE PRODUCCION UNITARIO'!D8 -> 289460.08 | E6: ='COSTO DE PRODUCCION UNITARIO'!E8 -> 320156.3 | F6: ='COSTO DE PRODUCCION UNITARIO'!F8 -> 364176.76 | G6: ='COSTO DE PRODUCCION UNITARIO'!G8 -> 483828.89 | H6: ='COSTO DE PRODUCCION UNITARIO'!H8 -> 567110.77 | I6: ='COSTO DE PRODUCCION UNITARIO'!I8 -> 624153.32 | ... K6: ='COSTO DE PRODUCCION UNITARIO'!K8 -> 836290.85
A7: =Producto disponible para la venta -> 0 | B7: =SUM(B5,B6) -> 214626.89 | C7: =SUM(C5,C6) -> 200589.93 | D7: =SUM(D5,D6) -> 289460.08 | E7: =SUM(E5,E6) -> 320156.3 | F7: =SUM(F5,F6) -> 364176.76 | G7: =SUM(G5,G6) -> 483828.89 | H7: =SUM(H5,H6) -> 567110.77 | I7: =SUM(I5,I6) -> 624153.32 | ... K7: =SUM(K5,K6) -> 836290.85
A8: - Inventario final | B8: 0 | C8: 0 | D8: 0 | E8: 0 | F8: 0 | G8: 0 | H8: 0 | I8: 0 | J8: 0 | K8: 0
A9: =Costo de venta -> 0 | B9: =B7-B8 -> 214626.89 | C9: =C7-C8 -> 200589.93 | D9: =D7-D8 -> 289460.08 | E9: =E7-E8 -> 320156.3 | F9: =F7-F8 -> 364176.76 | G9: =G7-G8 -> 483828.89 | H9: =H7-H8 -> 567110.77 | I9: =I7-I8 -> 624153.32 | ... K9: =K7-K8 -> 836290.85

Sheet ESTADO DE RESULTADOS
A1: Estado de Resultados - MuseIQ
A4: Concepto | B4: Año 1 | C4: Año 2 | D4: Año 3 | E4: Año 4 | F4: Año 5 | G4: Año 6 | H4: Año 7 | I4: Año 8 | J4: Año 9 | K4: Año 10
A5: Ventas totales | B5: ='INGRESOS'!B19 -> 412776 | C5: ='INGRESOS'!C19 -> 172842.24 | D5: ='INGRESOS'!D19 -> 421847.79 | E5: ='INGRESOS'!E19 -> 510557.02 | F5: ='INGRESOS'!F19 -> 683679.07 | G5: ='INGRESOS'!G19 -> 1041645.7 | H5: ='INGRESOS'!H19 -> 1328770.7 | I5: ='INGRESOS'!I19 -> 1406687.2 | ... K5: ='INGRESOS'!K19 -> 2130107.8
A6: Costo de venta | B6: ='COSTO DE VENTA'!B9 -> 214626.89 | C6: ='COSTO DE VENTA'!C9 -> 200589.93 | D6: ='COSTO DE VENTA'!D9 -> 289460.08 | E6: ='COSTO DE VENTA'!E9 -> 320156.3 | F6: ='COSTO DE VENTA'!F9 -> 364176.76 | G6: ='COSTO DE VENTA'!G9 -> 483828.89 | H6: ='COSTO DE VENTA'!H9 -> 567110.77 | I6: ='COSTO DE VENTA'!I9 -> 624153.32 | ... K6: ='COSTO DE VENTA'!K9 -> 836290.85
A7: Utilidad bruta en ventas | B7: =B5-B6 -> 198149.11 | C7: =C5-C6 -> -27747.69 | D7: =D5-D6 -> 132387.71 | E7: =E5-E6 -> 190400.72 | F7: =F5-F6 -> 319502.31 | G7: =G5-G6 -> 557816.82 | H7: =H5-H6 -> 761659.89 | I7: =I5-I6 -> 782533.89 | ... K7: =K5-K6 -> 1293817
A8: Total gastos de operacion | B8: =B9+B10 -> 157216.01 | C8: =C9+C10 -> 155650.33 | D8: =D9+D10 -> 166485.44 | E8: =E9+E10 -> 200366.84 | F8: =F9+F10 -> 227451.25 | G8: =G9+G10 -> 213003.59 | H8: =H9+H10 -> 227631.41 | I8: =I9+I10 -> 260613.74 | ... K8: =K9+K10 -> 297036.94
A9: Gastos de venta | B9: ='GASTOS_ADM_VTAS_FINANZAS'!B8 -> 56771.27 | C9: ='GASTOS_ADM_VTAS_FINANZAS'!C8 -> 52631 | D9: ='GASTOS_ADM_VTAS_FINANZAS'!D8 -> 60788.54 | E9: ='GASTOS_ADM_VTAS_FINANZAS'!E8 -> 91885.27 | F9: ='GASTOS_ADM_VTAS_FINANZAS'!F8 -> 99378.17 | G9: ='GASTOS_ADM_VTAS_FINANZAS'!G8 -> 111618.78 | H9: ='GASTOS_ADM_VTAS_FINANZAS'!H8 -> 122220.01 | I9: ='GASTOS_ADM_VTAS_FINANZAS'!I8 -> 151014.68 | ... K9: ='GASTOS_ADM_VTAS_FINANZAS'!K8 -> 178553.36
A10: Gastos de administracion | B10: ='GASTOS_ADM_VTAS_FINANZAS'!B15 -> 100444.74 | C10: ='GASTOS_ADM_VTAS_FINANZAS'!C15 -> 103019.33 | D10: ='GASTOS_ADM_VTAS_FINANZAS'!D15 -> 105696.9 | E10: ='GASTOS_ADM_VTAS_FINANZAS'!E15 -> 108481.58 | F10: ='GASTOS_ADM_VTAS_FINANZAS'!F15 -> 128073.08 | G10: ='GASTOS_ADM_VTAS_FINANZAS'!G15 -> 101384.81 | H10: ='GASTOS_ADM_VTAS_FINANZAS'!H15 -> 105411.4 | I10: ='GASTOS_ADM_VTAS_FINANZAS'!I15 -> 109599.05 | ... K10: ='GASTOS_ADM_VTAS_FINANZAS'!K15 -> 118483.58
A11: Utilidad de operacion | B11: =B7-B8 -> 40933.09 | C11: =C7-C8 -> -183398.02 | D11: =D7-D8 -> -34097.73 | E11: =E7-E8 -> -9966.12 | F11: =F7-F8 -> 92051.05 | G11: =G7-G8 -> 344813.23 | H11: =H7-H8 -> 534028.48 | I11: =I7-I8 -> 521920.15 | ... K11: =K7-K8 -> 996780.04
A12: Gastos financieros | B12: ='GASTOS_ADM_VTAS_FINANZAS'!B20 -> 32400 | C12: ='GASTOS_ADM_VTAS_FINANZAS'!C20 -> 32400 | D12: ='GASTOS_ADM_VTAS_FINANZAS'!D20 -> 32400 | E12: ='GASTOS_ADM_VTAS_FINANZAS'!E20 -> 28968.51 | F12: ='GASTOS_ADM_VTAS_FINANZAS'!F20 -> 24919.36 | G12: ='GASTOS_ADM_VTAS_FINANZAS'!G20 -> 20141.35 | H12: ='GASTOS_ADM_VTAS_FINANZAS'!H20 -> 14503.31 | I12: ='GASTOS_ADM_VTAS_FINANZAS'!I20 -> 7850.41 | ... K12: ='GASTOS_ADM_VTAS_FINANZAS'!K20 -> 0
A13: Utilidad antes del I.R. | B13: =B11-B12 -> 8533.09 | C13: =C11-C12 -> -215798.02 | D13: =D11-D12 -> -66497.73 | E13: =E11-E12 -> -38934.63 | F13: =F11-F12 -> 67131.7 | G13: =G11-G12 -> 324671.88 | H13: =H11-H12 -> 519525.18 | I13: =I11-I12 -> 514069.74 | ... K13: =K11-K12 -> 996780.04
A14: Impuesto a la renta 29.5% | B14: =MAX(0,B13*0.295) -> 2517.26 | C14: =MAX(0,C13*0.295) -> 0 | D14: =MAX(0,D13*0.295) -> 0 | E14: =MAX(0,E13*0.295) -> 0 | F14: =MAX(0,F13*0.295) -> 19803.85 | G14: =MAX(0,G13*0.295) -> 95778.2 | H14: =MAX(0,H13*0.295) -> 153259.93 | I14: =MAX(0,I13*0.295) -> 151650.57 | ... K14: =MAX(0,K13*0.295) -> 294050.11
A15: Utilidad neta | B15: =B13-B14 -> 6015.83 | C15: =C13-C14 -> -215798.02 | D15: =D13-D14 -> -66497.73 | E15: =E13-E14 -> -38934.63 | F15: =F13-F14 -> 47327.85 | G15: =G13-G14 -> 228893.68 | H15: =H13-H14 -> 366265.25 | I15: =I13-I14 -> 362419.17 | ... K15: =K13-K14 -> 702729.93
A16: Reserva legal | B16: =MIN(MAX(0,B15*10%),24000.0) -> 601.58 | C16: =MIN(MAX(0,C15*10%),MAX(0,24000.0-SUM($B$16:B16))) -> 0 | D16: =MIN(MAX(0,D15*10%),MAX(0,24000.0-SUM($B$16:C16))) -> 0 | E16: =MIN(MAX(0,E15*10%),MAX(0,24000.0-SUM($B$16:D16))) -> 0 | F16: =MIN(MAX(0,F15*10%),MAX(0,24000.0-SUM($B$16:E16))) -> 4732.78 | G16: =MIN(MAX(0,G15*10%),MAX(0,24000.0-SUM($B$16:F16))) -> 18665.63 | H16: =MIN(MAX(0,H15*10%),MAX(0,24000.0-SUM($B$16:G16))) -> 0 | I16: =MIN(MAX(0,I15*10%),MAX(0,24000.0-SUM($B$16:H16))) -> 0 | J16: =MIN(MAX(0,J15*10%),MAX(0,24000.0-SUM($B$16:I16))) -> 0 | K16: =MIN(MAX(0,K15*10%),MAX(0,24000.0-SUM($B$16:J16))) -> 0
A17: Utilidad a distribuir | B17: =B15-B16 -> 5414.25 | C17: =C15-C16 -> -215798.02 | D17: =D15-D16 -> -66497.73 | E17: =E15-E16 -> -38934.63 | F17: =F15-F16 -> 42595.06 | G17: =G15-G16 -> 210228.04 | H17: =H15-H16 -> 366265.25 | I17: =I15-I16 -> 362419.17 | ... K17: =K15-K16 -> 702729.93

Sheet PRESUPUESTO CAJA
A1: Presupuesto de Caja - MuseIQ
A4: Concepto | B4: Año 0 | C4: Año 1 | D4: Año 2 | E4: Año 3 | F4: Año 4 | G4: Año 5 | H4: Año 6 | I4: Año 7 | J4: Año 8 | K4: Año 9 | L4: Año 10
A5: INGRESOS DE EFECTIVO
A6: Fondos propios | B6: 120000 | C6: 0 | D6: 0 | E6: 0 | F6: 0 | G6: 0 | H6: 0 | I6: 0 | J6: 0 | K6: 0 | L6: 0
A7: Financiamiento | B7: 180000 | C7: 0 | D7: 0 | E7: 0 | F7: 0 | G7: 0 | H7: 0 | I7: 0 | J7: 0 | K7: 0 | L7: 0
A8: Ingresos por venta de contado | B8: 0 | C8: ='INGRESOS'!B23 -> 165110.4 | D8: ='INGRESOS'!C23 -> 69136.9 | E8: ='INGRESOS'!D23 -> 168739.12 | F8: ='INGRESOS'!E23 -> 204222.81 | G8: ='INGRESOS'!F23 -> 273471.63 | H8: ='INGRESOS'!G23 -> 416658.28 | I8: ='INGRESOS'!H23 -> 531508.26 | J8: ='INGRESOS'!I23 -> 562674.88 | ... L8: ='INGRESOS'!K23 -> 852043.13
A9: Recuperacion cuentas por cobrar del año | B9: 0 | C9: ='INGRESOS'!B25 -> 198132.48 | D9: ='INGRESOS'!C25 -> 82964.28 | E9: ='INGRESOS'!D25 -> 202486.94 | F9: ='INGRESOS'!E25 -> 245067.37 | G9: ='INGRESOS'!F25 -> 328165.95 | H9: ='INGRESOS'!G25 -> 499989.94 | I9: ='INGRESOS'!H25 -> 637809.92 | J9: ='INGRESOS'!I25 -> 675209.86 | ... L9: ='INGRESOS'!K25 -> 1022451.8
A10: Cuentas por cobrar año anterior | B10: 0 | C10: ='INGRESOS'!B26 -> 0 | D10: ='INGRESOS'!C26 -> 49533.12 | E10: ='INGRESOS'!D26 -> 20741.07 | F10: ='INGRESOS'!E26 -> 50621.73 | G10: ='INGRESOS'!F26 -> 61266.84 | H10: ='INGRESOS'!G26 -> 82041.49 | I10: ='INGRESOS'!H26 -> 124997.48 | J10: ='INGRESOS'!I26 -> 159452.48 | ... L10: ='INGRESOS'!K26 -> 237218.86
A11: Total ingresos | B11: =SUM(B6:B10) -> 300000 | C11: =SUM(C6:C10) -> 363242.88 | D11: =SUM(D6:D10) -> 201634.29 | E11: =SUM(E6:E10) -> 391967.12 | F11: =SUM(F6:F10) -> 499911.91 | G11: =SUM(G6:G10) -> 662904.43 | H11: =SUM(H6:H10) -> 998689.71 | I11: =SUM(I6:I10) -> 1294315.7 | ... L11: =SUM(L6:L10) -> 2111713.8
A13: EGRESOS DE EFECTIVO
A14: Compra de activos fijos | B14: 118000 | C14: 0 | D14: 0 | E14: 0 | F14: 0 | G14: 0 | H14: 0 | I14: 0 | J14: 0 | K14: 0 | L14: 0
A15: Activos nominales | B15: 132000 | C15: 0 | D15: 0 | E15: 0 | F15: 0 | G15: 0 | H15: 0 | I15: 0 | J15: 0 | K15: 0 | L15: 0
A16: Planilla de produccion | B16: 0 | C16: 68068.893 | D16: 103034.81 | E16: 128651.64 | F16: 133797.71 | G16: 139149.62 | H16: 168002.33 | I16: 174722.42 | J16: 208580.62 | K16: 216923.84 | L16: 225600.79
A17: Costos indirectos de fabricacion | B17: 0 | C17: 28300 | D17: 38432 | E17: 39969.28 | F17: 41568.051 | G17: 43230.773 | H17: 44960.004 | I17: 46758.404 | J17: 48628.741 | K17: 50573.89 | L17: 52596.846
A18: Compra insumos y servicios directos | B18: 0 | C18: 92845.51 | D18: 50812.282 | E18: 99838.971 | F18: 127755.65 | G18: 169834.76 | H18: 259778.99 | I18: 336699.79 | J18: 363625.99 | K18: 499616.32 | L18: 552634.16
A19: Gastos de administracion | B19: 0 | C19: 64364.74 | D19: 66939.33 | E19: 69616.903 | F19: 72401.579 | G19: 96793.082 | H19: 100664.81 | I19: 104691.4 | J19: 108879.05 | K19: 113234.22 | L19: 117763.58
A20: Gastos de venta | B20: 0 | C20: 56771.273 | D20: 52631.004 | E20: 60788.541 | F20: 91885.266 | G20: 99378.17 | H20: 111618.78 | I20: 122220.01 | J20: 151014.68 | K20: 169902 | L20: 178553.36
A21: Impuesto a la renta pagado | B21: 0 | C21: 0 | D21: 2517.2625 | E21: 0 | F21: 0 | G21: 0 | H21: 19803.851 | I21: 95778.205 | J21: 153259.93 | K21: 151650.57 | L21: 268179.18
A22: Pago de intereses | B22: 0 | C22: 32400 | D22: 32400 | E22: 32400 | F22: 28968.512 | G22: 24919.356 | H22: 20141.352 | I22: 14503.307 | J22: 7850.4137 | K22: 0 | L22: 0
A23: Abono a capital | B23: 0 | C23: 0 | D23: 0 | E23: 19063.823 | F23: 22495.311 | G23: 26544.468 | H23: 31322.472 | I23: 36960.517 | J23: 43613.41 | K23: 0 | L23: 0
A24: Total egresos | B24: =SUM(B14:B23) -> 250000 | C24: =SUM(C14:C23) -> 342750.42 | D24: =SUM(D14:D23) -> 346766.69 | E24: =SUM(E14:E23) -> 450329.16 | F24: =SUM(F14:F23) -> 518872.07 | G24: =SUM(G14:G23) -> 599850.23 | H24: =SUM(H14:H23) -> 756292.58 | I24: =SUM(I14:I23) -> 932334.05 | ... L24: =SUM(L14:L23) -> 1395327.9
A26: Flujo de efectivo | B26: =B11-B24 -> 50000 | C26: =C11-C24 -> 20492.46 | D26: =D11-D24 -> -145132.4 | E26: =E11-E24 -> -58362.04 | F26: =F11-F24 -> -18960.16 | G26: =G11-G24 -> 63054.2 | H26: =H11-H24 -> 242397.13 | I26: =I11-I24 -> 361981.62 | ... L26: =L11-L24 -> 716385.83
A27: Saldo inicial | B27: =0 -> 0 | C27: =B28 -> 50000 | D27: =C28 -> 70492.46 | E27: =D28 -> -74639.93 | F27: =E28 -> -133001.97 | G27: =F28 -> -151962.13 | H27: =G28 -> -88907.93 | I27: =H28 -> 153489.2 | J27: =I28 -> 515470.82 | ... L27: =K28 -> 1533861.8
A28: Saldo final | B28: =B27+B26 -> 50000 | C28: =C27+C26 -> 70492.46 | D28: =D27+D26 -> -74639.93 | E28: =E27+E26 -> -133001.97 | F28: =F27+F26 -> -151962.13 | G28: =G27+G26 -> -88907.93 | H28: =H27+H26 -> 153489.2 | I28: =I27+I26 -> 515470.82 | ... L28: =L27+L26 -> 2250247.7
A30: Nota: si el saldo final es negativo, el proyecto requiere una linea temporal de capital de trabajo; se mantiene visible para no forzar caja perfecta.

Sheet BALANCE GENERAL PROYECTADO
A1: Balance General Proyectado - MuseIQ
A4: Concepto | B4: Año 1 | C4: Año 2 | D4: Año 3 | E4: Año 4 | F4: Año 5 | G4: Año 6 | H4: Año 7 | I4: Año 8 | J4: Año 9 | K4: Año 10
A5: ACTIVOS
A6: Caja y bancos | B6: ='PRESUPUESTO CAJA'!C28 -> 70492.46 | C6: ='PRESUPUESTO CAJA'!D28 -> -74639.93 | D6: ='PRESUPUESTO CAJA'!E28 -> -133001.97 | E6: ='PRESUPUESTO CAJA'!F28 -> -151962.13 | F6: ='PRESUPUESTO CAJA'!G28 -> -88907.93 | G6: ='PRESUPUESTO CAJA'!H28 -> 153489.2 | H6: ='PRESUPUESTO CAJA'!I28 -> 515470.82 | I6: ='PRESUPUESTO CAJA'!J28 -> 827355.2 | ... K6: ='PRESUPUESTO CAJA'!L28 -> 2250247.7
A7: Cuentas por cobrar | B7: ='INGRESOS'!B28 -> 49533.12 | C7: ='INGRESOS'!C28 -> 20741.07 | D7: ='INGRESOS'!D28 -> 50621.73 | E7: ='INGRESOS'!E28 -> 61266.84 | F7: ='INGRESOS'!F28 -> 82041.49 | G7: ='INGRESOS'!G28 -> 124997.48 | H7: ='INGRESOS'!H28 -> 159452.48 | I7: ='INGRESOS'!I28 -> 168802.47 | ... K7: ='INGRESOS'!K28 -> 255612.94
A8: Total activo circulante | B8: =SUM(B6,B7) -> 120025.58 | C8: =SUM(C6,C7) -> -53898.86 | D8: =SUM(D6,D7) -> -82380.23 | E8: =SUM(E6,E7) -> -90695.29 | F8: =SUM(F6,F7) -> -6866.44 | G8: =SUM(G6,G7) -> 278486.69 | H8: =SUM(H6,H7) -> 674923.3 | I8: =SUM(I6,I7) -> 996157.67 | ... K8: =SUM(K6,K7) -> 2505860.6
A9: Activo fijo neto | B9: ='DEPRECIACIONES AMORTIZACION'!B12 -> 93800 | C9: ='DEPRECIACIONES AMORTIZACION'!C12 -> 69600 | D9: ='DEPRECIACIONES AMORTIZACION'!D12 -> 45400 | E9: ='DEPRECIACIONES AMORTIZACION'!E12 -> 21200 | F9: ='DEPRECIACIONES AMORTIZACION'!F12 -> 9000 | G9: ='DEPRECIACIONES AMORTIZACION'!G12 -> 7200 | H9: ='DEPRECIACIONES AMORTIZACION'!H12 -> 5400 | I9: ='DEPRECIACIONES AMORTIZACION'!I12 -> 3600 | ... K9: ='DEPRECIACIONES AMORTIZACION'!K12 -> 0
A10: Activo intangible neto | B10: ='DEPRECIACIONES AMORTIZACION'!B24 -> 105600 | C10: ='DEPRECIACIONES AMORTIZACION'!C24 -> 79200 | D10: ='DEPRECIACIONES AMORTIZACION'!D24 -> 52800 | E10: ='DEPRECIACIONES AMORTIZACION'!E24 -> 26400 | F10: ='DEPRECIACIONES AMORTIZACION'!F24 -> 0 | G10: ='DEPRECIACIONES AMORTIZACION'!G24 -> 0 | H10: ='DEPRECIACIONES AMORTIZACION'!H24 -> 0 | I10: ='DEPRECIACIONES AMORTIZACION'!I24 -> 0 | ... K10: ='DEPRECIACIONES AMORTIZACION'!K24 -> 0
A11: TOTAL ACTIVOS | B11: =SUM(B8,B9,B10) -> 319425.58 | C11: =SUM(C8,C9,C10) -> 94901.14 | D11: =SUM(D8,D9,D10) -> 15819.77 | E11: =SUM(E8,E9,E10) -> -43095.29 | F11: =SUM(F8,F9,F10) -> 2133.56 | G11: =SUM(G8,G9,G10) -> 285686.69 | H11: =SUM(H8,H9,H10) -> 680323.3 | I11: =SUM(I8,I9,I10) -> 999757.67 | ... K11: =SUM(K8,K9,K10) -> 2505860.6
A13: PASIVOS
A14: Cuentas por pagar | B14: ='COSTOS'!B23 -> 10892.49 | C14: ='COSTOS'!C23 -> 4683.33 | D14: ='COSTOS'!D23 -> 11163.51 | E14: ='COSTOS'!E23 -> 13678.41 | F14: ='COSTOS'!F23 -> 18320.02 | G14: ='COSTOS'!G23 -> 28327.59 | H14: ='COSTOS'!H23 -> 36177.74 | I14: ='COSTOS'!I23 -> 38415.72 | ... K14: ='COSTOS'!K23 -> 58486.39
A15: Ptmo. corto plazo | B15: ='GASTOS_ADM_VTAS_FINANZAS'!B21 -> 0 | C15: ='GASTOS_ADM_VTAS_FINANZAS'!C21 -> 0 | D15: ='GASTOS_ADM_VTAS_FINANZAS'!D21 -> 19063.82 | E15: ='GASTOS_ADM_VTAS_FINANZAS'!E21 -> 22495.31 | F15: ='GASTOS_ADM_VTAS_FINANZAS'!F21 -> 26544.47 | G15: ='GASTOS_ADM_VTAS_FINANZAS'!G21 -> 31322.47 | H15: ='GASTOS_ADM_VTAS_FINANZAS'!H21 -> 36960.52 | I15: ='GASTOS_ADM_VTAS_FINANZAS'!I21 -> 43613.41 | ... K15: ='GASTOS_ADM_VTAS_FINANZAS'!K21 -> 0
A16: Impuesto a la renta por pagar | B16: ='ESTADO DE RESULTADOS'!B14 -> 2517.26 | C16: ='ESTADO DE RESULTADOS'!C14 -> 0 | D16: ='ESTADO DE RESULTADOS'!D14 -> 0 | E16: ='ESTADO DE RESULTADOS'!E14 -> 0 | F16: ='ESTADO DE RESULTADOS'!F14 -> 19803.85 | G16: ='ESTADO DE RESULTADOS'!G14 -> 95778.2 | H16: ='ESTADO DE RESULTADOS'!H14 -> 153259.93 | I16: ='ESTADO DE RESULTADOS'!I14 -> 151650.57 | ... K16: ='ESTADO DE RESULTADOS'!K14 -> 294050.11
A17: Total pasivo circulante | B17: =SUM(B14,B15,B16) -> 13409.75 | C17: =SUM(C14,C15,C16) -> 4683.33 | D17: =SUM(D14,D15,D16) -> 30227.33 | E17: =SUM(E14,E15,E16) -> 36173.72 | F17: =SUM(F14,F15,F16) -> 64668.34 | G17: =SUM(G14,G15,G16) -> 155428.26 | H17: =SUM(H14,H15,H16) -> 226398.19 | I17: =SUM(I14,I15,I16) -> 233679.7 | ... K17: =SUM(K14,K15,K16) -> 352536.5
A18: Ptmo. largo plazo | B18: =MAX(0,'GASTOS_ADM_VTAS_FINANZAS'!B23-'GASTOS_ADM_VTAS_FINANZAS'!C21) -> 180000 | C18: =MAX(0,'GASTOS_ADM_VTAS_FINANZAS'!C23-'GASTOS_ADM_VTAS_FINANZAS'!D21) -> 160936.18 | D18: =MAX(0,'GASTOS_ADM_VTAS_FINANZAS'!D23-'GASTOS_ADM_VTAS_FINANZAS'!E21) -> 138440.87 | E18: =MAX(0,'GASTOS_ADM_VTAS_FINANZAS'!E23-'GASTOS_ADM_VTAS_FINANZAS'!F21) -> 111896.4 | F18: =MAX(0,'GASTOS_ADM_VTAS_FINANZAS'!F23-'GASTOS_ADM_VTAS_FINANZAS'!G21) -> 80573.93 | G18: =MAX(0,'GASTOS_ADM_VTAS_FINANZAS'!G23-'GASTOS_ADM_VTAS_FINANZAS'!H21) -> 43613.41 | H18: =MAX(0,'GASTOS_ADM_VTAS_FINANZAS'!H23-'GASTOS_ADM_VTAS_FINANZAS'!I21) -> 0 | I18: =MAX(0,'GASTOS_ADM_VTAS_FINANZAS'!I23-'GASTOS_ADM_VTAS_FINANZAS'!J21) -> 0 | J18: =MAX(0,'GASTOS_ADM_VTAS_FINANZAS'!J23-'GASTOS_ADM_VTAS_FINANZAS'!K21) -> 0 | K18: =MAX(0,'GASTOS_ADM_VTAS_FINANZAS'!K23-0) -> 0
A19: TOTAL PASIVOS | B19: =SUM(B17,B18) -> 193409.75 | C19: =SUM(C17,C18) -> 165619.5 | D19: =SUM(D17,D18) -> 168668.2 | E19: =SUM(E17,E18) -> 148070.12 | F19: =SUM(F17,F18) -> 145242.26 | G19: =SUM(G17,G18) -> 199041.67 | H19: =SUM(H17,H18) -> 226398.19 | I19: =SUM(I17,I18) -> 233679.7 | ... K19: =SUM(K17,K18) -> 352536.5
A21: PATRIMONIO
A22: Capital social | B22: ='PLAN DE INVERSION'!B9 -> 120000 | C22: ='PLAN DE INVERSION'!B9 -> 120000 | D22: ='PLAN DE INVERSION'!B9 -> 120000 | E22: ='PLAN DE INVERSION'!B9 -> 120000 | F22: ='PLAN DE INVERSION'!B9 -> 120000 | G22: ='PLAN DE INVERSION'!B9 -> 120000 | H22: ='PLAN DE INVERSION'!B9 -> 120000 | I22: ='PLAN DE INVERSION'!B9 -> 120000 | J22: ='PLAN DE INVERSION'!B9 -> 120000 | K22: ='PLAN DE INVERSION'!B9 -> 120000
A23: Reserva legal acumulada | B23: =SUM('ESTADO DE RESULTADOS'!$B$16:B16) -> 601.58 | C23: =SUM('ESTADO DE RESULTADOS'!$B$16:C16) -> 601.58 | D23: =SUM('ESTADO DE RESULTADOS'!$B$16:D16) -> 601.58 | E23: =SUM('ESTADO DE RESULTADOS'!$B$16:E16) -> 601.58 | F23: =SUM('ESTADO DE RESULTADOS'!$B$16:F16) -> 5334.37 | G23: =SUM('ESTADO DE RESULTADOS'!$B$16:G16) -> 24000 | H23: =SUM('ESTADO DE RESULTADOS'!$B$16:H16) -> 24000 | I23: =SUM('ESTADO DE RESULTADOS'!$B$16:I16) -> 24000 | ... K23: =SUM('ESTADO DE RESULTADOS'!$B$16:K16) -> 24000
A24: Utilidad acumulada | B24: =SUM('ESTADO DE RESULTADOS'!$B$17:B17) -> 5414.25 | C24: =SUM('ESTADO DE RESULTADOS'!$B$17:C17) -> -210383.78 | D24: =SUM('ESTADO DE RESULTADOS'!$B$17:D17) -> -276881.51 | E24: =SUM('ESTADO DE RESULTADOS'!$B$17:E17) -> -315816.14 | F24: =SUM('ESTADO DE RESULTADOS'!$B$17:F17) -> -273221.08 | G24: =SUM('ESTADO DE RESULTADOS'!$B$17:G17) -> -62993.03 | H24: =SUM('ESTADO DE RESULTADOS'!$B$17:H17) -> 303272.21 | I24: =SUM('ESTADO DE RESULTADOS'!$B$17:I17) -> 665691.38 | ... K24: =SUM('ESTADO DE RESULTADOS'!$B$17:K17) -> 2009324.1
A25: TOTAL PATRIMONIO | B25: =SUM(B22,B23,B24) -> 126015.83 | C25: =SUM(C22,C23,C24) -> -89782.19 | D25: =SUM(D22,D23,D24) -> -156279.92 | E25: =SUM(E22,E23,E24) -> -195214.56 | F25: =SUM(F22,F23,F24) -> -147886.71 | G25: =SUM(G22,G23,G24) -> 81006.97 | H25: =SUM(H22,H23,H24) -> 447272.21 | I25: =SUM(I22,I23,I24) -> 809691.38 | ... K25: =SUM(K22,K23,K24) -> 2153324.1
A26: Diferencia de cuadre referencial | B26: =B11-B19-B25 -> 0 | C26: =C11-C19-C25 -> 19063.82 | D26: =D11-D19-D25 -> 3431.49 | E26: =E11-E19-E25 -> 4049.16 | F26: =F11-F19-F25 -> 4778 | G26: =G11-G19-G25 -> 5638.04 | H26: =H11-H19-H25 -> 6652.89 | I26: =I11-I19-I25 -> -43613.41 | ... K26: =K11-K19-K25 -> 0

Sheet RAZONES FINANCIERAS
A1: Razones Financieras - MuseIQ
A4: Concepto | B4: Año 1 | C4: Año 2 | D4: Año 3 | E4: Año 4 | F4: Año 5 | G4: Año 6 | H4: Año 7 | I4: Año 8 | J4: Año 9 | K4: Año 10
A5: Indice de solvencia | B5: =IFERROR('BALANCE GENERAL PROYECTADO'!B8/'BALANCE GENERAL PROYECTADO'!B17,0) -> 8.9506188 | C5: =IFERROR('BALANCE GENERAL PROYECTADO'!C8/'BALANCE GENERAL PROYECTADO'!C17,0) -> -11.508668 | D5: =IFERROR('BALANCE GENERAL PROYECTADO'!D8/'BALANCE GENERAL PROYECTADO'!D17,0) -> -2.7253556 | E5: =IFERROR('BALANCE GENERAL PROYECTADO'!E8/'BALANCE GENERAL PROYECTADO'!E17,0) -> -2.5072149 | F5: =IFERROR('BALANCE GENERAL PROYECTADO'!F8/'BALANCE GENERAL PROYECTADO'!F17,0) -> -0.10617934 | G5: =IFERROR('BALANCE GENERAL PROYECTADO'!G8/'BALANCE GENERAL PROYECTADO'!G17,0) -> 1.7917377 | H5: =IFERROR('BALANCE GENERAL PROYECTADO'!H8/'BALANCE GENERAL PROYECTADO'!H17,0) -> 2.9811338 | I5: =IFERROR('BALANCE GENERAL PROYECTADO'!I8/'BALANCE GENERAL PROYECTADO'!I17,0) -> 4.2629192 | ... K5: =IFERROR('BALANCE GENERAL PROYECTADO'!K8/'BALANCE GENERAL PROYECTADO'!K17,0) -> 7.1080884
A6: Capital de trabajo neto | B6: ='BALANCE GENERAL PROYECTADO'!B8-'BALANCE GENERAL PROYECTADO'!B17 -> 106615.83 | C6: ='BALANCE GENERAL PROYECTADO'!C8-'BALANCE GENERAL PROYECTADO'!C17 -> -58582.19 | D6: ='BALANCE GENERAL PROYECTADO'!D8-'BALANCE GENERAL PROYECTADO'!D17 -> -112607.57 | E6: ='BALANCE GENERAL PROYECTADO'!E8-'BALANCE GENERAL PROYECTADO'!E17 -> -126869 | F6: ='BALANCE GENERAL PROYECTADO'!F8-'BALANCE GENERAL PROYECTADO'!F17 -> -71534.78 | G6: ='BALANCE GENERAL PROYECTADO'!G8-'BALANCE GENERAL PROYECTADO'!G17 -> 123058.42 | H6: ='BALANCE GENERAL PROYECTADO'!H8-'BALANCE GENERAL PROYECTADO'!H17 -> 448525.11 | I6: ='BALANCE GENERAL PROYECTADO'!I8-'BALANCE GENERAL PROYECTADO'!I17 -> 762477.97 | ... K6: ='BALANCE GENERAL PROYECTADO'!K8-'BALANCE GENERAL PROYECTADO'!K17 -> 2153324.1
A7: Prueba del acido | B7: =IFERROR('BALANCE GENERAL PROYECTADO'!B8/'BALANCE GENERAL PROYECTADO'!B17,0) -> 8.9506188 | C7: =IFERROR('BALANCE GENERAL PROYECTADO'!C8/'BALANCE GENERAL PROYECTADO'!C17,0) -> -11.508668 | D7: =IFERROR('BALANCE GENERAL PROYECTADO'!D8/'BALANCE GENERAL PROYECTADO'!D17,0) -> -2.7253556 | E7: =IFERROR('BALANCE GENERAL PROYECTADO'!E8/'BALANCE GENERAL PROYECTADO'!E17,0) -> -2.5072149 | F7: =IFERROR('BALANCE GENERAL PROYECTADO'!F8/'BALANCE GENERAL PROYECTADO'!F17,0) -> -0.10617934 | G7: =IFERROR('BALANCE GENERAL PROYECTADO'!G8/'BALANCE GENERAL PROYECTADO'!G17,0) -> 1.7917377 | H7: =IFERROR('BALANCE GENERAL PROYECTADO'!H8/'BALANCE GENERAL PROYECTADO'!H17,0) -> 2.9811338 | I7: =IFERROR('BALANCE GENERAL PROYECTADO'!I8/'BALANCE GENERAL PROYECTADO'!I17,0) -> 4.2629192 | ... K7: =IFERROR('BALANCE GENERAL PROYECTADO'!K8/'BALANCE GENERAL PROYECTADO'!K17,0) -> 7.1080884
A8: Rotacion de cuentas por cobrar | B8: =IFERROR('ESTADO DE RESULTADOS'!B5/'BALANCE GENERAL PROYECTADO'!B7,0) -> 8.3333333 | C8: =IFERROR('ESTADO DE RESULTADOS'!C5/'BALANCE GENERAL PROYECTADO'!C7,0) -> 8.3333333 | D8: =IFERROR('ESTADO DE RESULTADOS'!D5/'BALANCE GENERAL PROYECTADO'!D7,0) -> 8.3333333 | E8: =IFERROR('ESTADO DE RESULTADOS'!E5/'BALANCE GENERAL PROYECTADO'!E7,0) -> 8.3333333 | F8: =IFERROR('ESTADO DE RESULTADOS'!F5/'BALANCE GENERAL PROYECTADO'!F7,0) -> 8.3333333 | G8: =IFERROR('ESTADO DE RESULTADOS'!G5/'BALANCE GENERAL PROYECTADO'!G7,0) -> 8.3333333 | H8: =IFERROR('ESTADO DE RESULTADOS'!H5/'BALANCE GENERAL PROYECTADO'!H7,0) -> 8.3333333 | I8: =IFERROR('ESTADO DE RESULTADOS'!I5/'BALANCE GENERAL PROYECTADO'!I7,0) -> 8.3333333 | ... K8: =IFERROR('ESTADO DE RESULTADOS'!K5/'BALANCE GENERAL PROYECTADO'!K7,0) -> 8.3333333
A9: Plazo promedio de cobro | B9: =IFERROR(360/('ESTADO DE RESULTADOS'!B5/'BALANCE GENERAL PROYECTADO'!B7),0) -> 43.2 | C9: =IFERROR(360/('ESTADO DE RESULTADOS'!C5/'BALANCE GENERAL PROYECTADO'!C7),0) -> 43.2 | D9: =IFERROR(360/('ESTADO DE RESULTADOS'!D5/'BALANCE GENERAL PROYECTADO'!D7),0) -> 43.2 | E9: =IFERROR(360/('ESTADO DE RESULTADOS'!E5/'BALANCE GENERAL PROYECTADO'!E7),0) -> 43.2 | F9: =IFERROR(360/('ESTADO DE RESULTADOS'!F5/'BALANCE GENERAL PROYECTADO'!F7),0) -> 43.2 | G9: =IFERROR(360/('ESTADO DE RESULTADOS'!G5/'BALANCE GENERAL PROYECTADO'!G7),0) -> 43.2 | H9: =IFERROR(360/('ESTADO DE RESULTADOS'!H5/'BALANCE GENERAL PROYECTADO'!H7),0) -> 43.2 | I9: =IFERROR(360/('ESTADO DE RESULTADOS'!I5/'BALANCE GENERAL PROYECTADO'!I7),0) -> 43.2 | ... K9: =IFERROR(360/('ESTADO DE RESULTADOS'!K5/'BALANCE GENERAL PROYECTADO'!K7),0) -> 43.2
A10: Rotacion de cuentas por pagar | B10: =IFERROR('COSTOS'!B8/'BALANCE GENERAL PROYECTADO'!B14,0) -> 9.5238095 | C10: =IFERROR('COSTOS'!C8/'BALANCE GENERAL PROYECTADO'!C14,0) -> 9.5238095 | D10: =IFERROR('COSTOS'!D8/'BALANCE GENERAL PROYECTADO'!D14,0) -> 9.5238095 | E10: =IFERROR('COSTOS'!E8/'BALANCE GENERAL PROYECTADO'!E14,0) -> 9.5238095 | F10: =IFERROR('COSTOS'!F8/'BALANCE GENERAL PROYECTADO'!F14,0) -> 9.5238095 | G10: =IFERROR('COSTOS'!G8/'BALANCE GENERAL PROYECTADO'!G14,0) -> 9.5238095 | H10: =IFERROR('COSTOS'!H8/'BALANCE GENERAL PROYECTADO'!H14,0) -> 9.5238095 | I10: =IFERROR('COSTOS'!I8/'BALANCE GENERAL PROYECTADO'!I14,0) -> 9.5238095 | ... K10: =IFERROR('COSTOS'!K8/'BALANCE GENERAL PROYECTADO'!K14,0) -> 9.5238095
A11: Plazo promedio de pago | B11: =IFERROR(360/('COSTOS'!B8/'BALANCE GENERAL PROYECTADO'!B14),0) -> 37.8 | C11: =IFERROR(360/('COSTOS'!C8/'BALANCE GENERAL PROYECTADO'!C14),0) -> 37.8 | D11: =IFERROR(360/('COSTOS'!D8/'BALANCE GENERAL PROYECTADO'!D14),0) -> 37.8 | E11: =IFERROR(360/('COSTOS'!E8/'BALANCE GENERAL PROYECTADO'!E14),0) -> 37.8 | F11: =IFERROR(360/('COSTOS'!F8/'BALANCE GENERAL PROYECTADO'!F14),0) -> 37.8 | G11: =IFERROR(360/('COSTOS'!G8/'BALANCE GENERAL PROYECTADO'!G14),0) -> 37.8 | H11: =IFERROR(360/('COSTOS'!H8/'BALANCE GENERAL PROYECTADO'!H14),0) -> 37.8 | I11: =IFERROR(360/('COSTOS'!I8/'BALANCE GENERAL PROYECTADO'!I14),0) -> 37.8 | ... K11: =IFERROR(360/('COSTOS'!K8/'BALANCE GENERAL PROYECTADO'!K14),0) -> 37.8
A12: Razon de endeudamiento | B12: =IFERROR('BALANCE GENERAL PROYECTADO'!B19/'BALANCE GENERAL PROYECTADO'!B11,0) -> 0.60549237 | C12: =IFERROR('BALANCE GENERAL PROYECTADO'!C19/'BALANCE GENERAL PROYECTADO'!C11,0) -> 1.7451794 | D12: =IFERROR('BALANCE GENERAL PROYECTADO'!D19/'BALANCE GENERAL PROYECTADO'!D11,0) -> 10.661865 | E12: =IFERROR('BALANCE GENERAL PROYECTADO'!E19/'BALANCE GENERAL PROYECTADO'!E11,0) -> -3.4358774 | F12: =IFERROR('BALANCE GENERAL PROYECTADO'!F19/'BALANCE GENERAL PROYECTADO'!F11,0) -> 68.07513 | G12: =IFERROR('BALANCE GENERAL PROYECTADO'!G19/'BALANCE GENERAL PROYECTADO'!G11,0) -> 0.69671316 | H12: =IFERROR('BALANCE GENERAL PROYECTADO'!H19/'BALANCE GENERAL PROYECTADO'!H11,0) -> 0.3327803 | I12: =IFERROR('BALANCE GENERAL PROYECTADO'!I19/'BALANCE GENERAL PROYECTADO'!I11,0) -> 0.23373634 | ... K12: =IFERROR('BALANCE GENERAL PROYECTADO'!K19/'BALANCE GENERAL PROYECTADO'!K11,0) -> 0.1406848
A13: Pasivo / Capital | B13: =IFERROR('BALANCE GENERAL PROYECTADO'!B19/'BALANCE GENERAL PROYECTADO'!B25,0) -> 1.5348052 | C13: =IFERROR('BALANCE GENERAL PROYECTADO'!C19/'BALANCE GENERAL PROYECTADO'!C25,0) -> -1.844681 | D13: =IFERROR('BALANCE GENERAL PROYECTADO'!D19/'BALANCE GENERAL PROYECTADO'!D25,0) -> -1.0792698 | E13: =IFERROR('BALANCE GENERAL PROYECTADO'!E19/'BALANCE GENERAL PROYECTADO'!E25,0) -> -0.75849935 | F13: =IFERROR('BALANCE GENERAL PROYECTADO'!F19/'BALANCE GENERAL PROYECTADO'!F25,0) -> -0.98211844 | G13: =IFERROR('BALANCE GENERAL PROYECTADO'!G19/'BALANCE GENERAL PROYECTADO'!G25,0) -> 2.4570933 | H13: =IFERROR('BALANCE GENERAL PROYECTADO'!H19/'BALANCE GENERAL PROYECTADO'!H25,0) -> 0.50617539 | I13: =IFERROR('BALANCE GENERAL PROYECTADO'!I19/'BALANCE GENERAL PROYECTADO'!I25,0) -> 0.28860342 | ... K13: =IFERROR('BALANCE GENERAL PROYECTADO'!K19/'BALANCE GENERAL PROYECTADO'!K25,0) -> 0.16371734
